```java
public class Ex26 {
  public static void main(String[] args) {
    try {
      int alpha = Integer.parseInt("THIS IS NOT A NUMBER. WAHAHA!");
    } catch(NumberFormatException e) {
      System.out.println("An attempt was made to parse a String which was not a number.");
    }

    try {
      int alpha = 5/0;
    } catch(ArithmeticException e) {
      System.out.println("Somebody tried to divide by 0. Oh no!");
    }

    try {
      int[] alpha = {1, 3, 6, 10, 15};
      // What could possibly go wrong here?
      System.out.println(alpha[5]);
      System.out.println(alpha[0] / 0);
    } catch(ArrayIndexOutOfBounds e) {
      System.out.println("You tried to access a non-existent array element!");
    } catch(ArithmeticException e) {
      System.out.println("Somebody tried to divide by 0. Oh no!");
    } catch(Exception e) {
      System.out.println("Some other error happened!");
    }

    try {
      int alpha = 5/0;
    } catch(ArithmeticException e) {
      System.out.println("Stop trying to divide by 0!!!");
    } finally {
      System.out.println("Finally always run, whether an error happens, or not!");
    }
  }
}
```

### Explanation
1. This exercise introduces the concept of `try-catch` blocks. Normally when an error, known as an `Exception` in Java occurs, the whole program crashes. Usually we don't want that. 
